Workbook

Sheet Main
J2: Price | K2: 284 | L2: 46090
B3: Firefly: Adobe's AI Suite | F3: Enterprise Software/ Marketing | G3: 25% of rev | J3: Shares | K3: 410.5 | L3: Q425
B4: Creative Cloud: Digital Art, Visual Media, Digital Editing, etc. Suite of tools package | F4: Creative Cloud | G4: 46% of rev | J4: MC | K4: =K3*K2 -> 116582
B5: AEP, AEM: Adobe's Enterprise Software | F5: CC Enterprise | G5: 43% of CC | H5: =0.46*0.43 -> 0.1978 | J5: Cash | K5: =5431+1164 -> 6595 | L5: Q425
B6: Acrobat: Industry Standard Document Tool | F6: CC NonEnt | G6: 57% of CC | J6: Debt | K6: =6210+469+125+361+508 -> 7673 | L6: Q425
F7: Acrobat | G7: 15% of rev | J7: EV | K7: =K4+K6-K5 -> 117660
B8: Semrush Acquisition 1H26 @ 1.9b | F8: Consumer | G8: 14% of rev | K8: =K2/(1.1*4*Model!G69) -> #DIV/0!
J9: CEO: Shantanu Narayen
B10: Todo: | J10: COO:
B11: Literature review for AI adoption curve,
B12: jevon's paradox & seat compression | F12: Adobe's future is highly dependent on the mangement's execution and if Jevon's Paradox will accelerate growth after seat diminishment
F13: The key drivers are: Enterprise Firefly adoption, AI generated content legality, Jevon's Paradox increasing industry adoption of tools, and Firefly/Adobe's GenAI ability to raise ARPU through increased use of gen tokens.
B14: Channel Checks
F15: Catalyst: Seat churn / metrics and Firefly adoption over the next 12-24 months will determine what happens next to the stock
B16: Management Research & Company History
F17: Consenses:
B18: GenAI current legality and future
F19: Bull Case: Adobe's management executes Firefly well and GenAI legality increases Firefly adoption among enterprise clients and allows them to drastically raise ARPU through the cost savings of increased productivity and less seats and Jevon's Paradox helps regain some seats. Depending on market dynamics it could raise the price from 350-400+
B20: Finish mapping out quarters and | F20: Base Case: Firefly gets some adoption in enterprise clients and enterprise seats get drastically cut. The stock remains relatively unchanged around 300
B21: creating a model to predict & track KPIs | F21: Bear Case: Jevon's Paradox never kicks in, enterprise clients don’t adopt firefly, and even non enterprise seats are cut. Drop to around the low 200s
B22: on a quarterly basis
F23: Notes:
B24: Map out KPI trends that will confirm theories | F24: Jevon's Paradox
F25: Art/visual media is highly elastic meaning more producivity will in the long run lead to a higher consumption/ growth rate for non-enterprise
B26: Transfer Monte Carlo simulation into python | F26: Firefly trained on images Adobe had the legal right to train on; Most AI models are trained on data skimmed from the internet
B27: for more functionality and reworking
F28: Moat: Barrier to entry -> refined industry standard many functions and large suite constant updates and proven reliability; User switching cost -> takes time to learn the tools and long standing company provides updates and longevity users want to not want to learn new tools;
F29: Management Quality:
F30: Innovation:
F31: Industry: High growth rate, elastic
F32: KPIs: CC Seats (seperated Enterprise & Non Enterprise), Firefly ARR, Enterprise ARPU, GenAI Tokens

Sheet Literature
A1: Main
B2: DOI | C2: Title | D2: Description
B3: https://doi.org/10.1093/pnasnexus/pgae052
D4: Image/Video Editing and Graphic Design 9% CAGR
D5: DAM Software 14% CAGR
D6: e-signature and digital document 10% cagr
B8: https://helpx.adobe.com/au/enterprise/kb/vip-select-discounts.html#:~:text=Table_title:%20Team%20products%20(all%20regions%2C%20except%20Japan),Communications%20Suite%2C%20FrameMaker%2C%20and%20RoboHelp:%207.50%25%20%7C | C8: Enterprise Discounts | D8: Up to 25% for enterprise commerical
B9: https://www.adobe.com/creativecloud/plans.html | C9: Pricing | D9: Adobe Firefly Enterprise: 200/mo without special pricing; Creative Cloud Enterprise: 100/mo without special pricing; Creative Cloud: 70/mo without special pricing, individual apps ~20/mo, schools 35/mo
B12: GenAI:
B16: Jevon's Paradox:
B20: SaaSpocalyse Channel Checks:
B23: https://pages.stern.nyu.edu/~adamodar/ | D23: Discount Rate assumptions

Sheet Model
A1: Main
C2: Q124 | D2: Q224 | E2: Q324 | F2: Q425 | G2: Q125 | H2: Q225 | I2: Q325 | J2: Q425 | K2: Q126 | L2: Q226 | M2: Q326 | N2: Q426 | P2: 2012 | Q2: =P2+1 -> 2013 | R2: =Q2+1 -> 2014 | S2: =R2+1 -> 2015 | T2: =S2+1 -> 2016 | U2: =T2+1 -> 2017 | V2: =U2+1 -> 2018 | W2: 2019 | X2: 2020 | Y2: =X2+1 -> 2021 | Z2: =Y2+1 -> 2022 | AA2: =Z2+1 -> 2023 | AB2: =AA2+1 -> 2024 | AC2: =AB2+1 -> 2025 | AD2: =AC2+1 -> 2026 | AE2: =AD2+1 -> 2027 | AF2: =AE2+1 -> 2028 | ... AH2: =AG2+1 -> 2030 | AI2: T
B3: Creative & Marketing | C3: 3550 | D3: 3640 | E3: 3720 | F3: 3840 | G3: 3920 | H3: 4020 | I3: 4120 | J3: 4250 | K3: 4300 | AC3: =AD3*0.92 -> 16468 | AD3: 17900
B4: Business & Consumers | C4: 1340 | D4: 1390 | E4: 1440 | F4: 1500 | G4: 1530 | H4: 1600 | I4: 1650 | J4: 1720 | K4: 1750 | AC4: =AD4*0.92 -> 6808 | AD4: 7400
B6: KPIs
B7: ARR | C7: 20640 | D7: 21250 | E7: 21860 | F7: 22730 | G7: 23060 | H7: 23840 | I7: 24280 | J7: 25660 | AC7: 25660
B8: Firefly ARR | F8: =F18-F17 -> 2700 | J8: =J18-J17 -> 4000
B9: CC Non Enterprise Seat Churn
B10: CC Enterprise Seat Churn | AE10: =-(AE31/AD31-1) -> 0.5
B11: GenAI Tokens | C11: 2300 | D11: =D12-C12 -> 2500 | E11: =E12-D12 -> 2700 | F11: =F12-E12 -> 3510 | G11: =G12-F12 -> 4790 | H11: =H12-G12 -> 4000 | I11: =H11*1.12 -> 4480 | J11: =F11*1.43 -> 5019.3
B12: Cumulative Generations | C12: 6500 | D12: 9000 | E12: =D12*1.3 -> 11700 | F12: =E12*1.3 -> 15210 | G12: 20000 | H12: 24000 | I12: =H12+I11 -> 28480 | J12: =I12+J11 -> 33499.3
B13: RPOs | C13: 17580 | D13: 17860 | E13: 18140 | F13: 19960 | G13: 19690 | H13: 19690 | I13: 20440 | J13: 22520
B14: cRPO | C14: 0.68 | D14: 0.68 | E14: 0.69 | F14: 0.67 | G14: 0.67 | H14: 0.67 | I14: 0.67 | J14: 0.65
B15: customers ARR >10m | F15: =J15/1.25 -> 120 | J15: 150
B16: AEP + Apps ARR | J16: "30% yoy"
B17: GenStudio ARR | F17: =J17/1.25 -> 800 | J17: 1000
B18: "AI-influenced" ARR | F18: 3500 | J18: 5000 | K18: =J18*1.1 -> 5500 | L18: =K18*1.1 -> 6050 | M18: =L18*1.1 -> 6655 | N18: =J18*1.43 -> 7150
B19: "AI-first" ARR | G19: 125 | J19: 250
B20: TAM | AB20: 205000 | AE20: 293000
B21: Document Cloud TAM | AB21: 32000 | AC21: =AB21*1.14 -> 36480 | AD21: =AC21*1.14 -> 41587.2 | AE21: 47000
B22: CC TAM | AB22: 63000 | AE22: 91000
B23: Experience Cloud TAM | AB23: 110000 | AE23: 155000
B24: Firefly Seats | F24: =F18/(10*12) -> 29.166667 | J24: =J18/(10*12) -> 41.666667
B25: Tokens/Firefly per year | F25: =(F11*4)/F24 -> 481.37143 | J25: =(J11*4)/J24 -> 481.8528
B27: CC Seats | AC27: 40 | AD27: =AD29+AD31 -> 43.460606 | AE27: =AE29+AE31 -> 42.705212 | AF27: =AF29+AF31 -> 46.267568 | AG27: =AG29+AG31 -> 50.132426 | AH27: =AH29+AH31 -> 54.326087
B28: CC ARPU/month | AC28: =AC36/AC27/12 -> 28.958333 | AD28: =AD36/AD27/12 -> 29.234416 | AE28: =AE36/AE27/12 -> 29.457984 | AF28: =AF36/AF27/12 -> 29.743576 | AG28: =AG36/AG27/12 -> 30.037849 | AH28: =AH36/AH27/12 -> 30.341
B29: CC Non-Enterprise Seats | AC29: =AC27-AC31 -> 33.484848 | AD29: =AC29*1.08 -> 36.163636 | AE29: =AD29*1.08 -> 39.056727 | AF29: =AE29*1.08 -> 42.181265 | AG29: =AF29*1.08 -> 45.555767 | AH29: =AG29*1.08 -> 49.200228
B30: CC Non-Enterprise ARPU/month | AC30: ='CC Model'!C4 -> 20 | AD30: =AC30 -> 20 | AE30: =AD30*1.05 -> 21 | AF30: =AE30 -> 21 | AG30: =AF30 -> 21 | AH30: =AG30 -> 21
B31: CC Enterprise Seats | AC31: ='CC Model'!C6 -> 6.5151515 | AD31: =AC31*1.12 -> 7.2969697 | AE31: =AD31*0.5 -> 3.6484848 | AF31: =AE31*1.12 -> 4.086303 | AG31: =AF31*1.12 -> 4.5766594 | AH31: =AG31*1.12 -> 5.1258585
B32: CC Enterprise ARPU/month | AC32: ='CC Model'!C5 -> 75 | AD32: =AC32 -> 75 | AE32: 120 | AF32: =AE32 -> 120 | AG32: =AF32 -> 120 | AH32: =AG32 -> 120
B34: Marketing (AEP, AEM) | J34: "AEP >40%yoy" | Z34: =Y45 -> 3400 | AA34: =Z45 -> 3842 | AB34: =AA45 -> 4341.46 | AC34: =AB45 -> 4900 | AD34: =AC45 -> 5537 | AE34: =AD34*1.13 -> 6256.81 | AF34: =AE34*1.13 -> 7070.1953 | AG34: =AF34*1.13 -> 7989.3207 | AH34: =AG34*1.13 -> 9027.9324
B35: Creators & Creative (Creative Cloud)
B36: Creative Cloud+Firefly | P36: =P47-P39 -> 2600 | Z36: =Y43 -> 10300 | AA36: =Z43 -> 11433 | AB36: 12680 | AC36: =AB43 -> 13900 | AD36: =SUM(AD37:AD38) -> 15246.545 | AE36: =SUM(AE37:AE38) -> 15096.113 | AF36: =SUM(AF37:AF38) -> 16513.955 | AG36: =SUM(AG37:AG38) -> 18070.443 | AH36: =SUM(AH37:AH38) -> 19779.694
B37: Creative Cloud Enterprise | AC37: =AC32*12*AC31 -> 5863.6364 | AD37: =AD32*12*AD31 -> 6567.2727 | AE37: =AE32*12*AE31 -> 5253.8182 | AF37: =AF32*12*AF31 -> 5884.2764 | AG37: =AG32*12*AG31 -> 6590.3895 | AH37: =AH32*12*AH31 -> 7381.2363
B38: Creative Cloud non-Enterprise | AC38: =AC30*12*AC29 -> 8036.3636 | AD38: =AD30*12*AD29 -> 8679.2727 | AE38: =AE30*12*AE29 -> 9842.2953 | AF38: =AF30*12*AF29 -> 10629.679 | AG38: =AG30*12*AG29 -> 11480.053 | AH38: =AH30*12*AH29 -> 12398.457
B39: Acrobat+Express | P39: 400 | Z39: =Y42 -> 1900 | AA39: =Z42 -> 2337 | AB39: =AA42 -> 2874.51 | AC39: =AB42 -> 3500 | AD39: =AC42 -> 4305 | AE39: =AD39*1.2 -> 5166 | AF39: =AE39*1.2 -> 6199.2 | AG39: =AF39*1.2 -> 7439.04 | AH39: =AG39*1.2 -> 8926.848
B40: Other | Z40: =Z48-Y45 -> 1000 | AA40: =AA48-Z45 -> 1058 | AB40: =AB48-AA45 -> 1028.54 | AC40: =AC48-AB45 -> 950 | AD40: =AC40*0.95 -> 902.5 | AE40: =AD40*0.95 -> 857.375 | AF40: =AE40*0.95 -> 814.50625 | AG40: =AF40*0.95 -> 773.78094 | AH40: =AG40*0.95 -> 735.09189
B42: Document Cloud ARR | Y42: 1900 | Z42: =Y42*1.23 -> 2337 | AA42: =Z42*1.23 -> 2874.51 | AB42: 3500 | AC42: =AB42*1.23 -> 4305
B43: CC ARR | Y43: 10300 | Z43: =Y43*1.11 -> 11433 | AA43: =Z43*1.11 -> 12690.63 | AB43: 13900 | AC43: =AB43*1.1 -> 15290
B44: CC enterprise ARR | Y44: 1500 | Z44: 1800 | AA44: 1900 | AB44: 2200 | AC44: =AB44*1.18 -> 2596
...

Sheet Alpha
A1: Main
B2: Discount | C2: =C3+C4 -> 0.0862
B3: RFR | C3: 0.0416 | D3: 46090 | E3: T-Bond
B4: ERP | C4: 0.0446 | D4: 46023 | E4: Implied (source in literature)
B6: Intrinsic | C6: =Model!AL123 -> 325.45011
B7: Current | C7: =Main!K2 -> 284
B8: Diff | C8: =C6/C7-1 -> 0.1459511
B10: Risk
B11: Excess-Value from Price | C11: =Model!AL122-Main!K4 -> 17015.271 | D11: <- current excess intrinsic value from market
B12: At-Risk Value | C12: =Main!K4*0.2*0.5 -> 11658.2 | D12: <-20% of total rev, half of it is at risk (50% seat compression)
B13: Allowed Assumption Margin of Safety | C13: =D13*Model!AL122 -> 20039.591 | D13: 0.15 | E13: <- intrsinic value model assumptions (without at-risk value) allowed 15% margin of error (large stable company, smaller companies assumptions swing way more and require a lot greater >30%, >50% assumption margin of errors)
B14: Total Excess | C14: =C11-C12-C13 -> -14682.52
B16: Risk-Free Alpha | C16: =(Main!K4+C14)/Main!K4-1 -> -0.12594157
B17: Max Buy-Price | C17: =(C14+Main!K4+Main!K5-Main!K6)/Main!K3 -> 245.60653
B18: MoS | C18: =Model!AL123/Alpha!C17-1 -> 0.32508738 | D18: <- removing ai seat compression risk and assumption risk this is the MoS required for alpha to be generated
D19: at 0 excess value (MoS %) on average the stock has to return >= 0%; at > 0 excess value, stock > 0%
D20: % return meaning real yearly alpha (subtracting RFR and ERP) and adjusting for risk (max seat compression & assumption variability)

Sheet CC Model
A1: Main
B2: Total CC Revenue | C2: =Model!AC36 -> 13900 | E2: Logic:
B3: Total CC Seats | C3: 40 | E3: (12*15)x+(12*80)y=13900
A4: v | B4: Non-Enterprise ARPU/mo | C4: 20 | E4: x+y=40
A5: v | B5: Enterprise ARPU/mo | C5: =(100*0.75) -> 75 | E5: y=40-x
B6: Enterprise Seats | C6: =(C2-(C4*12*C3))/((C5*12)-(C4*12)) -> 6.5151515 | E6: (12*15)x+(12*80)(40-x)=13900
B7: Non-Enterprise Seats | C7: =C3-C6 -> 33.484848
E8: Variables:
E9: Non-Enterprise ARPU/mo
E10: Enterprise ARPU/mo
E11: Adjusted for yearly by multiplying by 12
E13: Knowns:
E14: CC Revenue/year
E15: CC Seats/year
E17: Unknowns:
E18: x=Enterprise Seats; y=Non-Enterprise Seats
E20: Sensitivity Analysis; End Value = ENT Revenue
C22: ='CC Model'!C6*'CC Model'!C5*12 -> 5863.6364 | D22: 10 | E22: 12.5 | F22: 15 | G22: 20 | H22: 25 | I22: NonENT ARPU
C23: 40 | D23: 12133.333 | E23: 11490.909 | F23: 10720 | G23: 8600 | H23: 5066.6667
C24: 50 | D24: 11375 | E24: 10533.333 | F24: 9571.4286 | G24: 7166.6667 | H24: 3800
C25: 60 | D25: 10920 | E25: 9978.9474 | F25: 8933.3333 | G25: 6450 | H25: 3257.1429
C26: 70 | D26: 10616.667 | E26: 9617.3913 | F26: 8527.2727 | G26: 6020 | H26: 2955.5556
C27: 80 | D27: 10400 | E27: 9362.963 | F27: 8246.1538 | G27: 5733.3333 | H27: 2763.6364
C28: 90 | D28: 10237.5 | E28: 9174.1935 | F28: 8040 | G28: 5528.5714 | H28: 2630.7692
C29: 100 | D29: 10111.111 | E29: 9028.5714 | F29: 7882.3529 | G29: 5375 | H29: 2533.3333
C30: 110 | D30: 10010 | E30: 8912.8205 | F30: 7757.8947 | G30: 5255.5556 | H30: 2458.8235
C31: 120 | D31: 9927.2727 | E31: 8818.6047 | F31: 7657.1429 | G31: 5160 | H31: 2400
C32: Ent ARPU

Sheet Management
A1: Main
B3: 2007 | C3: Current CEO takes over, was COO since 2005
B4: 2012 | C4: Adobe stagnates as its business model is outdated and not innovating
B5: 2014 | C5: Adobe transitions to a monthly subscription model and starts focusing on enterprise deals and software
B6: Post 2014 | C6: The new direction of the company which marks the current model of Adobe is very successful
B9: 2024 | C9: Firefly?
B10: 2026 | C10: Adobe GenAI seat reduction fears stock collapses ~40%

Sheet Q&A
A1: Main
B2: Interviewee | C2: Date | D2: Question | E2: Answer | F2: Notes
D3: Do genAI models destroy creative seats by automating tasks / increasing productivity? | E3: Management says AI acts as an accelerant and expands the TAM due to more need for fine-tuning, color-correction, compositing, and assembly
E4: Strategy for monetizing AI: higher-priced tiers that include AI capabilities, Acrobat AI assistant, shifting from seat-based pricing to consumption-based pricing. | F4: Even though there will be fewer seats, consumption will increase, and the need for fine-tuning outputs increase which leads to a total increase in TAM
D5: Are the prospects of Firefly's IP-safe training leading to more in-house AI model use than 3rd party?
D6: When will Adobe enforce hard caps on gen credits to drive consumption revenue? | E6: Management says they want to avoid generation anxiety currently
D7: ARR from seat vs AI-price hikes?

Sheet Monte Carlo Simulation
A1: Main
B2: Mean ARPU | C2: =J15 -> 90 | E2: =_xlfn.NORM.INV(RAND(), C2,C3) -> 59.680201 | G2: Todo:
B3: SD ARPU | C3: =J20 -> 22.730303 | G3: Add covariance to show correlation between ARPU and Seats instead of complete randomness
B4: Mean ENT Seats | C4: =J22 -> 6.9 | E4: =_xlfn.NORM.INV(RAND(), C4,C5) -> 5.6435802 | G4: Add limits to remove numbers that cannot occur such as negative seats
B5: SD ENT Seats | C5: =J27 -> 2.0716338
B6: Mean Growth | C6: =J29 -> 0.013333333 | E6: =_xlfn.NORM.INV(RAND(), C6,C7) -> 0.17879436
B7: SD Growth | C7: =J34 -> 0.2131249
B8: ENT Revenue | E8: =(E2*12)*E4*(1+E6) -> 4764.3567 | I8: Multiple | J8: =(J9+J10+J11)/3 -> 3.4242681
B9: Mean Multiple | C9: =J11 -> 3.4728042 | E9: =_xlfn.NORM.INV(RAND(), C9,C10) -> 3.3784564 | I9: Min | J9: 3
B10: SD Multiple | C10: =J13 -> 0.16419847 | I10: Max | J10: 3.8
E11: =($E$12+E8)*$E$9/Main!$K$3 -> 295.07123 | I11: Mode | J11: =Model!AJ67 -> 3.4728042
B12: NonENT Revenue | E12: =Model!AH34+Model!AH38+Model!AH39+Model!AH40 -> 31088.33 | I12: Variance | J12: =((J9^2)+(J10^2)+(J11^2)-(J9*J10)-(J9*J11)-(J10*J11))/18 -> 0.026961136
I13: SD | J13: =SQRT(J12) -> 0.16419847
B14: =E8 -> 4764.3567 | D14: =E11 -> 295.07123 | F14: ENT Revenue
A15: 1 | B15: 10785.19 | C15: 1 | D15: 304.26965 | F15: =AVERAGE(B15:B215) -> 7605.6405 | G15: 1000 iterations average | I15: ARPU | J15: =(J16+J17+J18)/3 -> 90
A16: =A15+1 -> 2 | B16: 5264.8231 | C16: =C15+1 -> 2 | D16: 270.47005 | F16: =F15/Model!AH37-1 -> 0.030401986 | G16: Diff | I16: Min | J16: 40 | K16: <- firefly failure, seat compression
A17: =A16+1 -> 3 | B17: 11619.271 | C17: =C16+1 -> 3 | D17: 360.0217 | I17: Max | J17: 150 | K17: <- firefly adoption
A18: =A17+1 -> 4 | B18: 4080.5478 | C18: =C17+1 -> 4 | D18: 345.93272 | F18: Share Price | I18: Mode | J18: 80 | K18: <- normal
A19: =A18+1 -> 5 | B19: 4518.4813 | C19: =C18+1 -> 5 | D19: 302.38575 | F19: =AVERAGE(D15:D215) -> 329.7518 | G19: 1000 iterations average | I19: Variance | J19: =((J16^2)+(J17^2)+(J18^2)-(J16*J17)-(J16*J18)-(J17*J18))/18 -> 516.66667
A20: =A19+1 -> 6 | B20: 9838.6723 | C20: =C19+1 -> 6 | D20: 340.75085 | F20: =F19/Model!$AL$123-1 -> 0.013217643 | G20: Diff | H20: a | I20: SD | J20: =SQRT(J19) -> 22.730303
A21: =A20+1 -> 7 | B21: 5419.9502 | C21: =C20+1 -> 7 | D21: 329.18836 | F21: =_xlfn.PERCENTILE.INC($D$15:$D$1014, 0.25) -> 302.34899 | G21: Bottom 25% Price
A22: =A21+1 -> 8 | B22: 4560.4596 | C22: =C21+1 -> 8 | D22: 337.85799 | F22: =F21/Model!$AL$123-1 -> -0.070982082 | G22: Diff | I22: Seats | J22: =(J23+J24+J25)/3 -> 6.9
A23: =A22+1 -> 9 | B23: 8789.4216 | C23: =C22+1 -> 9 | D23: 329.0193 | F23: =_xlfn.PERCENTILE.INC($D$15:$D$1014, 0.75) -> 347.34552 | G23: Top 25% Price | I23: Min | J23: 2.4 | K23: based on ARPU calculations max vs min
A24: =A23+1 -> 10 | B24: 10478.816 | C24: =C23+1 -> 10 | D24: 385.65503 | F24: =F23/Model!$AL$123-1 -> 0.067277308 | G24: Diff | I24: Max | J24: 12.4
A25: =A24+1 -> 11 | B25: 8997.3102 | C25: =C24+1 -> 11 | D25: 356.28185 | I25: Mode | J25: 5.9
A26: =A25+1 -> 12 | B26: 9974.9266 | C26: =C25+1 -> 12 | D26: 332.36598 | I26: Variance | J26: =((J23^2)+(J24^2)+(J25^2)-(J23*J24)-(J23*J25)-(J24*J25))/18 -> 4.2916667
A27: =A26+1 -> 13 | B27: 7363.4728 | C27: =C26+1 -> 13 | D27: 303.23567 | I27: SD | J27: =SQRT(J26) -> 2.0716338
A28: =A27+1 -> 14 | B28: 3958.0057 | C28: =C27+1 -> 14 | D28: 331.61836
A29: =A28+1 -> 15 | B29: 7752.2539 | C29: =C28+1 -> 15 | D29: 316.59198 | F29: Optimal Portfolio Allocation | I29: Growth | J29: =(J30+J31+J32)/3 -> 0.013333333
A30: =A29+1 -> 16 | B30: 5900.2121 | C30: =C29+1 -> 16 | D30: 329.34693 | F30: Current Share | G30: =Main!K2*(1/1) -> 284 | I30: Min | J30: -0.4 | K30: <-decelerated growth & seat compression
A31: =A30+1 -> 17 | B31: 9173.3316 | C31: =C30+1 -> 17 | D31: 376.9784 | I31: Max | J31: 0.6 | K31: <- seat compression accelerated growth Jevon's paradox
A32: =A31+1 -> 18 | B32: 6800.2198 | C32: =C31+1 -> 18 | D32: 310.98348 | F32: WinRate | G32: =COUNTIF(D15:D1014, ">"&G30)/1000 -> 0.939 | I32: Mode | J32: -0.16 | K32: <- 5 years normal growth with 50% seat compression
A33: =A32+1 -> 19 | B33: 7286.4867 | C33: =C32+1 -> 19 | D33: 303.37939 | F33: LossRate | G33: =1-G32 -> 0.061 | I33: Variance | J33: =((J30^2)+(J31^2)+(J32^2)-(J30*J31)-(J30*J32)-(J31*J32))/18 -> 0.045422222
A34: =A33+1 -> 20 | B34: 7448.4755 | C34: =C33+1 -> 20 | D34: 308.43196 | I34: SD | J34: =SQRT(J33) -> 0.2131249
A35: =A34+1 -> 21 | B35: 13287.787 | C35: =C34+1 -> 21 | D35: 322.24257 | F35: Avg Win | G35: =AVERAGEIF(D15:D1014, ">"&G30)/G30 - 1 -> 0.16383061
A36: =A35+1 -> 22 | B36: 8255.0603 | C36: =C35+1 -> 22 | D36: 323.91161 | F36: Avg Loss | G36: =1 - (AVERAGEIF(D15:D1014, "<="&G30)/G30) -> 0.030307945
A37: =A36+1 -> 23 | B37: 5197.4101 | C37: =C36+1 -> 23 | D37: 288.97324 | F37: W/L Ratio | G37: =G35/G36 -> 5.4055335
A38: =A37+1 -> 24 | B38: 17552.37 | C38: =C37+1 -> 24 | D38: 397.42554
A39: =A38+1 -> 25 | B39: 5227.4821 | C39: =C38+1 -> 25 | D39: 337.886 | F39: Optimal Kelly Allocation | G39: =G32 - (G33/G37) -> 0.92771527
A40: =A39+1 -> 26 | B40: 7190.2106 | C40: =C39+1 -> 26 | D40: 325.43683 | F40: Half-Kelly | G40: =G39/2 -> 0.46385763
...
