Workbook

Sheet Main
B2: Name | C2: Indication | D2: Approved | E2: MOA | F2: Economics | G2: IP | J2: Price | K2: 22
B3: Elevidys (delandistrogen moxeparvovec-rokl) | C3: DMD | E3: AAV Gene Therapy | F3: Roche | J3: Shares | K3: =98.277 -> 98.277 | L3: Q125
B4: Exondys (eteplirsen) | C4: DMD | E4: PMO | J4: MC | K4: =K3*K2 -> 2162.094
B5: Vyondys (golodirsen) | C5: DMD | E5: PMO | J5: Cash | K5: =240.8+281.9 -> 522.7 | L5: Q125
B6: Amondys (casimersen) | C6: DMD | E6: PMO | J6: Debt | K6: =1138.3+205.46+325+47.4+1 -> 1717.16 | L6: Q125
D7: Phase | J7: EV | K7: =K4+K6-K5 -> 3356.554
B8: SRP-9003 (biridistrogene xeboparvovec) | C8: LGMD2E | D8: III | E8: Gene Therapy
B9: SRP-9004 (patidistrogene bexoparvovec) | E9: Gene Therapy | J9: CEO: Douglas S. Ingram
B10: SRP-6004 | E10: Gene Therapy | J10: COO: Ian M. Estepan
B11: SRP-1001 (ARO-DUX4) | E11: siRNA | J11: R&D: Louise R. Rodino-Klapac, Ph.D.
B12: SRP-1003 (ARO-DM1) | E12: siRNA | J12: CCO: Patrick E. Moss, Pharm.D.
B13: SRP-1004 (ARO-ATXN2) | E13: siRNA | J13: CFO: Ryan H. Wong
B14: SRP-1002 (ARO-MMP7) | E14: siRNA
J15: Richard Barry - Part of Board of Directors
B16: 45857 | C16: FDA voluntarily asked SRPT to halt Elevidys shipments; SRPT refused
C17: FDA remove request to halt

Sheet Model
A1: Main | Q1: Entry | U1: Exit
C2: Q124 | D2: Q224 | E2: Q324 | F2: Q424 | G2: Q125 | H2: Q225 | I2: Q325 | J2: Q425 | L2: 2020 | M2: =L2+1 -> 2021 | N2: =M2+1 -> 2022 | O2: =N2+1 -> 2023 | P2: =O2+1 -> 2024 | Q2: =P2+1 -> 2025 | R2: =Q2+1 -> 2026 | S2: =R2+1 -> 2027 | T2: =S2+1 -> 2028 | U2: =T2+1 -> 2029
B3: Elevidys | R3: =elevidys!D30 -> 395.5968 | S3: =elevidys!E30 -> 399.55277 | T3: =elevidys!F30 -> 403.5483 | U3: =elevidys!G30 -> 407.58378
B4: PMOs | R4: 1000 | S4: 1000 | T4: 1000 | U4: 1000
B5: Revenue | C5: 359.5 | G5: 611.5 | H5: =G5*1 -> 611.5 | I5: =H5*1 -> 611.5 | J5: =I5*1 -> 611.5 | N5: 933 | O5: 1243.3 | P5: 1901.98 | Q5: 2300 | R5: =SUM(R3:R4) -> 1395.5968 | S5: =SUM(S3:S4) -> 1399.5528 | T5: =SUM(T3:T4) -> 1403.5483 | U5: =SUM(U3:U4) -> 1407.5838
B6: COGS | N6: 139.98 | O6: 150.34 | P6: 319.1 | Q6: =Q5*(1-Q20) -> 345 | R6: =R5*(1-R20) -> 209.33952 | S6: =S5*(1-S20) -> 209.93292 | T6: =T5*(1-T20) -> 210.53224 | U6: =U5*(1-U20) -> 211.13757
B7: Gross Profit | L7: =L5-L6 -> 0 | M7: =M5-M6 -> 0 | N7: =N5-N6 -> 793.02 | O7: =O5-O6 -> 1092.96 | P7: =P5-P6 -> 1582.88 | Q7: =Q5-Q6 -> 1955 | R7: =R5-R6 -> 1186.2573 | S7: =S5-S6 -> 1189.6199 | ... U7: =U5-U6 -> 1196.4462
B8: R&D | N8: 877 | O8: 877.4 | P8: 804.5 | W8: ROIC | X8: 0.02
B9: SG&A | N9: 451.4 | O9: 481.9 | P9: 557.9 | Q9: =P9*1.1 -> 613.69 | R9: =Q9*1 -> 613.69 | S9: =R9*1 -> 613.69 | T9: =S9*1 -> 613.69 | U9: =T9*1 -> 613.69 | W9: Maturity | X9: -0.03
B10: Operating Expenses | L10: =SUM(L8:L9) -> 0 | M10: =SUM(M8:M9) -> 0 | N10: =SUM(N8:N9) -> 1328.4 | O10: =SUM(O8:O9) -> 1359.3 | P10: =SUM(P8:P9) -> 1362.4 | Q10: =SUM(Q8:Q9) -> 613.69 | R10: =SUM(R8:R9) -> 613.69 | S10: =SUM(S8:S9) -> 613.69 | ... U10: =SUM(U8:U9) -> 613.69 | W10: Discount | X10: 0.095
B11: EBITDA | L11: =L7-L10 -> 0 | M11: =M7-M10 -> 0 | N11: =N7-N10 -> -535.38 | O11: =O7-O10 -> -266.34 | P11: =P7-P10 -> 220.48 | Q11: =Q7-Q10 -> 1341.31 | R11: =R7-R10 -> 572.56728 | S11: =S7-S10 -> 575.92985 | ... U11: =U7-U10 -> 582.75621 | W11: NPV | X11: =NPV(X10,Q15:DD15)+Main!K5-Main!K6 -> 3454.0187
B12: Interest Income | N12: -28.3 | O12: 33 | P12: 42.7 | Q12: =G23*$X$8 -> -23.88 | R12: =Q23*$X$8 -> -15.9976 | S12: =R23*$X$8 -> -7.0924851 | T12: =S23*$X$8 -> 2.0089128 | U12: =T23*$X$8 -> 11.310272 | W12: Share | X12: =X11/Main!K3 -> 35.145749
B13: Pretax Income | L13: =L11+L12 -> 0 | M13: =M11+M12 -> 0 | N13: =N11+N12 -> -563.68 | O13: =O11+O12 -> -233.34 | P13: =P11+P12 -> 263.18 | Q13: =Q11+Q12 -> 1317.43 | R13: =R11+R12 -> 556.56968 | S13: =S11+S12 -> 568.83737 | ... U13: =U11+U12 -> 594.06648 | X13: =X12/Main!K2-1 -> 0.59753403
B14: Tax | N14: 13.5 | O14: 15.9 | P14: 25.5 | Q14: =Q13*0.2 -> 263.486 | R14: =R13*0.2 -> 111.31394 | S14: =S13*0.2 -> 113.76747 | T14: =T13*0.2 -> 116.26699 | U14: =U13*0.2 -> 118.8133
B15: Net Income | L15: =L13-L14 -> 0 | M15: =M13-M14 -> 0 | N15: =N13-N14 -> -577.18 | O15: =O13-O14 -> -249.24 | P15: =P13-P14 -> 237.68 | Q15: =Q13-Q14 -> 1053.944 | R15: =R13-R14 -> 445.25574 | S15: =S13-S14 -> 455.06989 | ... U15: =U13-U14 -> 475.25319 | V15: =U15*(1+$X$9) -> 460.99559 | W15: =V15*(1+$X$9) -> 447.16572 | X15: =W15*(1+$X$9) -> 433.75075 | Y15: =X15*(1+$X$9) -> 420.73823 | Z15: =Y15*(1+$X$9) -> 408.11608 | AA15: =Z15*(1+$X$9) -> 395.8726 | AB15: =AA15*(1+$X$9) -> 383.99642 | AC15: =AB15*(1+$X$9) -> 372.47653 | ... DI15: =DH15*(1+$X$9) -> 28.835308
B16: Shares | N16: 87.559 | O16: 92.398 | P16: 95.1 | Q16: =P16 -> 95.1 | R16: =Q16 -> 95.1 | S16: =R16 -> 95.1 | T16: =S16 -> 95.1 | U16: =T16 -> 95.1
B17: EPS | L17: =L15/L16 -> #DIV/0! | M17: =M15/M16 -> #DIV/0! | N17: =N15/N16 -> -6.591898 | O17: =O15/O16 -> -2.697461 | P17: =P15/P16 -> 2.4992639 | Q17: =Q15/Q16 -> 11.082482 | R17: =R15/R16 -> 4.6819742 | S17: =S15/S16 -> 4.7851724 | ... U17: =U15/U16 -> 4.9974047
B19: Revenue y/y | O19: =O5/N5-1 -> 0.33258307 | P19: =P5/O5-1 -> 0.52978364 | Q19: =Q5/P5-1 -> 0.20926613 | R19: =R5/Q5-1 -> -0.39321878 | S19: =S5/R5-1 -> 0.0028346067 | T19: =T5/S5-1 -> 0.0028548603 | U19: =U5/T5-1 -> 0.0028752006
B20: Gross Profit | C20: =C7/C5 -> 0 | D20: =D7/D5 -> #DIV/0! | E20: =E7/E5 -> #DIV/0! | F20: =F7/F5 -> #DIV/0! | G20: =G7/G5 -> 0 | H20: =H7/H5 -> 0 | I20: =I7/I5 -> 0 | J20: =J7/J5 -> 0 | L20: =L7/L5 -> #DIV/0! | M20: =M7/M5 -> #DIV/0! | N20: =N7/N5 -> 0.84996785 | O20: =O7/O5 -> 0.87907987 | P20: =P7/P5 -> 0.83222747 | Q20: 0.85 | R20: 0.85 | S20: 0.85 | T20: 0.85 | U20: 0.85
B21: SG&A y/y | O21: =O9/N9-1 -> 0.067567568 | P21: =P9/O9-1 -> 0.15770907 | Q21: =Q9/P9-1 -> 0.1 | R21: =R9/Q9-1 -> 0 | S21: =S9/R9-1 -> 0 | T21: =T9/S9-1 -> 0 | U21: =U9/T9-1 -> 0
B23: Net Cash | G23: =G24-G37 -> -1194 | P23: =P24-P37 -> 217.7 | Q23: =Q24-Q37 -> -799.88 | R23: =R24-R37 -> -354.62426 | S23: =S24-S37 -> 100.44564 | T23: =T24-T37 -> 565.51361 | U23: =U24-U37 -> 1040.7668
B24: Cash | G24: 523 | P24: =1103+251.8 -> 1354.8 | Q24: 523 | R24: =Q24+R15 -> 968.25574 | S24: =R24+S15 -> 1423.3256 | T24: =S24+T15 -> 1888.3936 | U24: =T24+U15 -> 2363.6468
B25: AR | P25: 602
B26: Inventories | P26: 750
B27: Prepaids & Deposits | P27: 276.3
B28: OCA | P28: =90.5 -> 90.5
B29: PP&E | P29: 340.3
B30: ROU | P30: 148.3
B31: ONCA | P31: =188+133+80 -> 401
B32: Assets | P32: =SUM(P24:P31) -> 3963.2
B34: AP | P34: 214.4
B35: Accrued Expenses | P35: 373.5
B36: Deferred Revenue | P36: =130+325 -> 455
B37: Debt | G37: 1717 | P37: =1137.1 -> 1137.1 | Q37: =Q69 -> 1322.88 | R37: =Q37 -> 1322.88 | S37: =R37 -> 1322.88 | T37: =S37 -> 1322.88 | U37: =T37 -> 1322.88
B38: OCL | P38: 13.5
B39: Lease Liablities | P39: 192.5
B40: Contingent | P40: 47.4
B41: ONCL | P41: 1.8
B42: Liablities | P42: =SUM(P34:P41) -> 2435.2
B44: SE | P44: =P32-P42 -> 1528
...

Sheet IP
A1: Main
B2: Patent | C2: Relevance | D2: Title | E2: Notes

Sheet Literature
A1: Main
B2: Read | C2: Relevance | D2: Topic | E2: Title
E3: search terms="

Sheet elevidys
A1: Main
B2: Brand | C2: Elevidys, SRP-9001
B3: Generic | C3: delandistrogen moxeparvovec-rokl
B4: Indication | C4: DMD
B5: MOA | C5: AAV-based Gene Therapy
B6: Competition
B7: Regulatory
B8: Economics | C8: Roche
C9: Additionally, we are eligible to receive up to $1.7 billion in development, regulatory and sales milestone payments with respect to ELEVIDYS
C10: In addition, the Roche Agreement provides that Roche will pay us royalties on net sales of ELEVIDYS, at a tiered royalty rate based on the average cost to manufacture ELEVIDYS.
B11: Clinical Trials
C12: Phase III "EXPEDITION" in DMD n=400 NCT:NCT05967351
C15: Phase III "ENVISION" in DMD n=148 NCT:NCT05881408
C18: Phase I/II "" in DMD n= NCT:NCT03769116
C21: Phase I/IIa "" in DMD n= NCT:NCT03375164
C24: Ambulatory
C25: 2025 | D25: =C25+1 -> 2026 | E25: =D25+1 -> 2027 | F25: =E25+1 -> 2028 | G25: =F25+1 -> 2029 | H25: =G25+1 -> 2030 | I25: =H25+1 -> 2031 | J25: =I25+1 -> 2032 | K25: =J25+1 -> 2033 | ... O25: =N25+1 -> 2037
B26: US Patient Pool | C26: =15000*0.8 -> 12000 | D26: =C26*1.01 -> 12120 | E26: =D26*1.01 -> 12241.2 | F26: =E26*1.01 -> 12363.612 | G26: =F26*1.01 -> 12487.248 | H26: =G26*1.01 -> 12612.121 | I26: =H26*1.01 -> 12738.242 | J26: =I26*1.01 -> 12865.624 | K26: =J26*1.01 -> 12994.28 | ... O26: =N26*1.01 -> 13521.9
B27: Treated | C27: 0 | D27: =D26*0.02 -> 242.4 | E27: =E26*0.02 -> 244.824 | F27: =F26*0.02 -> 247.27224 | G27: =G26*0.02 -> 249.74496 | H27: =H26*0.02 -> 252.24241 | I27: =I26*0.02 -> 254.76484 | J27: =J26*0.02 -> 257.31248 | K27: =K26*0.02 -> 259.88561 | ... O27: =O26*0.02 -> 270.43801
B28: Price | C28: 3200000 | D28: 3200000 | E28: 3200000 | F28: 3200000 | G28: 3200000 | H28: 3200000 | I28: 3200000 | J28: 3200000 | K28: 3200000 | L28: 3200000 | M28: 3200000 | N28: 3200000 | O28: 3200000
B29: Revenue | C29: =C28*C27/1000000*0.85 -> 0 | D29: =D28*D27/1000000*0.85 -> 659.328 | E29: =E28*E27/1000000*0.85 -> 665.92128 | F29: =F28*F27/1000000*0.85 -> 672.58049 | G29: =G28*G27/1000000*0.85 -> 679.3063 | H29: =H28*H27/1000000*0.85 -> 686.09936 | I29: =I28*I27/1000000*0.85 -> 692.96035 | J29: =J28*J27/1000000*0.85 -> 699.88996 | ... O29: =O28*O27/1000000*0.85 -> 735.59138
B30: risk-adj Revenue | D30: =D29*0.6 -> 395.5968 | E30: =E29*0.6 -> 399.55277 | F30: =F29*0.6 -> 403.5483 | G30: =G29*0.6 -> 407.58378 | H30: =H29*0.6 -> 411.65962 | I30: =I29*0.6 -> 415.77621 | J30: =J29*0.6 -> 419.93397 | K30: =K29*0.6 -> 424.13331 | ... O30: =O29*0.6 -> 441.35483
B32: Discount | C32: 0.15
B33: NPV | C33: =NPV(C32,C29:XFD29)*0.2+1700 -> 2346.5414
C34: non-ambulatory approval adds ~1.1b
C35: "elevidys is contraindicated in patients w/ any deletion in exon 8 and or exon 9 in the duchenne gene"

Sheet exondys
A1: Main
B2: Brand
B3: Generic
B4: Indication | C4: targets the most frequent series of mutations that cause DMD
B5: MOA
B6: Competition
B7: Regulatory
B8: Clinical Trials
C9: "approx 13% of patients are amenable to exon 51 skipping"

Sheet vyondys
A1: Main
B2: Brand
B3: Generic
B4: Indication | C4: DMD patients w/ mutation of the dystrophin gene that is amenable to exondys skipping
B5: MOA
B6: Competition
B7: Regulatory | C7: Approved 2019
B8: Clinical Trials
C9: Skips exon 45 of the dystrophin gene
C10: "approx 8% of DMD patients are amenable to exon 53 skipping"

Sheet amondys
A1: Main
B2: Brand
B3: Generic
B4: Indication
B5: MOA
B6: Competition
B7: Regulatory | C7: Approved 2021
B8: Clinical Trials
C9: "approx. 8% of patients are amenable to exon 45 skipping"

Sheet SRP-9003
A1: Main
B2: Brand | C2: SRP-9003
B3: Generic | C3: bidridistrogene xeboparvovec
B4: Indication | C4: LGMD2E
B5: MOA
B6: Competition
B7: Regulatory
B8: Clinical Trials
C9: Phase I/IIa "" in LGMD n= NCT:
C11: Phase III "EMERGENE" in LGMD n= NCT:
